Workbook

Sheet Summary
A1: Module | B1: Total | C1: P0 | D1: P1 | E1: P2 | F1: P3 | G1: Pass | H1: Fail | I1: Blocked | J1: Not yet run
A2: 01-auth-and-access | B2: 165 | C2: 0 | D2: 80 | E2: 77 | F2: 8 | G2: =COUNTIF('01-auth-and-access'!G2:G166,"Pass") | H2: =COUNTIF('01-auth-and-access'!G2:G166,"Fail") | I2: =COUNTIF('01-auth-and-access'!G2:G166,"Blocked") | J2: =B2-COUNTIF('01-auth-and-access'!G2:G166,"Pass")-COUNTIF('01-auth-and-access'!G2:G166,"Fail")-COUNTIF('01-auth-and-access'!G2:G166,"Blocked")-COUNTIF('01-auth-and-access'!G2:G166,"NA")
A3: 02-storefront-catalog | B3: 192 | C3: 0 | D3: 38 | E3: 136 | F3: 18 | G3: =COUNTIF('02-storefront-catalog'!G2:G193,"Pass") | H3: =COUNTIF('02-storefront-catalog'!G2:G193,"Fail") | I3: =COUNTIF('02-storefront-catalog'!G2:G193,"Blocked") | J3: =B3-COUNTIF('02-storefront-catalog'!G2:G193,"Pass")-COUNTIF('02-storefront-catalog'!G2:G193,"Fail")-COUNTIF('02-storefront-catalog'!G2:G193,"Blocked")-COUNTIF('02-storefront-catalog'!G2:G193,"NA")
A4: 03-cart-wishlist | B4: 97 | C4: 0 | D4: 47 | E4: 48 | F4: 2 | G4: =COUNTIF('03-cart-wishlist'!G2:G98,"Pass") | H4: =COUNTIF('03-cart-wishlist'!G2:G98,"Fail") | I4: =COUNTIF('03-cart-wishlist'!G2:G98,"Blocked") | J4: =B4-COUNTIF('03-cart-wishlist'!G2:G98,"Pass")-COUNTIF('03-cart-wishlist'!G2:G98,"Fail")-COUNTIF('03-cart-wishlist'!G2:G98,"Blocked")-COUNTIF('03-cart-wishlist'!G2:G98,"NA")
A5: 04-checkout-payment-orders | B5: 153 | C5: 0 | D5: 69 | E5: 82 | F5: 2 | G5: =COUNTIF('04-checkout-payment-orders'!G2:G154,"Pass") | H5: =COUNTIF('04-checkout-payment-orders'!G2:G154,"Fail") | I5: =COUNTIF('04-checkout-payment-orders'!G2:G154,"Blocked") | J5: =B5-COUNTIF('04-checkout-payment-orders'!G2:G154,"Pass")-COUNTIF('04-checkout-payment-orders'!G2:G154,"Fail")-COUNTIF('04-checkout-payment-orders'!G2:G154,"Blocked")-COUNTIF('04-checkout-payment-orders'!G2:G154,"NA")
A6: 05-customer-account | B6: 147 | C6: 0 | D6: 69 | E6: 77 | F6: 1 | G6: =COUNTIF('05-customer-account'!G2:G148,"Pass") | H6: =COUNTIF('05-customer-account'!G2:G148,"Fail") | I6: =COUNTIF('05-customer-account'!G2:G148,"Blocked") | J6: =B6-COUNTIF('05-customer-account'!G2:G148,"Pass")-COUNTIF('05-customer-account'!G2:G148,"Fail")-COUNTIF('05-customer-account'!G2:G148,"Blocked")-COUNTIF('05-customer-account'!G2:G148,"NA")
A7: 06-admin-catalog-masters | B7: 238 | C7: 0 | D7: 131 | E7: 107 | F7: 0 | G7: =COUNTIF('06-admin-catalog-masters'!G2:G239,"Pass") | H7: =COUNTIF('06-admin-catalog-masters'!G2:G239,"Fail") | I7: =COUNTIF('06-admin-catalog-masters'!G2:G239,"Blocked") | J7: =B7-COUNTIF('06-admin-catalog-masters'!G2:G239,"Pass")-COUNTIF('06-admin-catalog-masters'!G2:G239,"Fail")-COUNTIF('06-admin-catalog-masters'!G2:G239,"Blocked")-COUNTIF('06-admin-catalog-masters'!G2:G239,"NA")
A8: 07-offers-coupons-pricing | B8: 123 | C8: 0 | D8: 60 | E8: 63 | F8: 0 | G8: =COUNTIF('07-offers-coupons-pricing'!G2:G124,"Pass") | H8: =COUNTIF('07-offers-coupons-pricing'!G2:G124,"Fail") | I8: =COUNTIF('07-offers-coupons-pricing'!G2:G124,"Blocked") | J8: =B8-COUNTIF('07-offers-coupons-pricing'!G2:G124,"Pass")-COUNTIF('07-offers-coupons-pricing'!G2:G124,"Fail")-COUNTIF('07-offers-coupons-pricing'!G2:G124,"Blocked")-COUNTIF('07-offers-coupons-pricing'!G2:G124,"NA")
A9: 08-admin-orders-delivery-returns | B9: 140 | C9: 0 | D9: 79 | E9: 61 | F9: 0 | G9: =COUNTIF('08-admin-orders-delivery-return'!G2:G141,"Pass") | H9: =COUNTIF('08-admin-orders-delivery-return'!G2:G141,"Fail") | I9: =COUNTIF('08-admin-orders-delivery-return'!G2:G141,"Blocked") | J9: =B9-COUNTIF('08-admin-orders-delivery-return'!G2:G141,"Pass")-COUNTIF('08-admin-orders-delivery-return'!G2:G141,"Fail")-COUNTIF('08-admin-orders-delivery-return'!G2:G141,"Blocked")-COUNTIF('08-admin-orders-delivery-return'!G2:G141,"NA")
A10: 09-inventory-purchases | B10: 128 | C10: 0 | D10: 72 | E10: 56 | F10: 0 | G10: =COUNTIF('09-inventory-purchases'!G2:G129,"Pass") | H10: =COUNTIF('09-inventory-purchases'!G2:G129,"Fail") | I10: =COUNTIF('09-inventory-purchases'!G2:G129,"Blocked") | J10: =B10-COUNTIF('09-inventory-purchases'!G2:G129,"Pass")-COUNTIF('09-inventory-purchases'!G2:G129,"Fail")-COUNTIF('09-inventory-purchases'!G2:G129,"Blocked")-COUNTIF('09-inventory-purchases'!G2:G129,"NA")
A11: 10-agents-referral-commission-payout | B11: 145 | C11: 0 | D11: 97 | E11: 48 | F11: 0 | G11: =COUNTIF('10-agents-referral-commission-p'!G2:G146,"Pass") | H11: =COUNTIF('10-agents-referral-commission-p'!G2:G146,"Fail") | I11: =COUNTIF('10-agents-referral-commission-p'!G2:G146,"Blocked") | J11: =B11-COUNTIF('10-agents-referral-commission-p'!G2:G146,"Pass")-COUNTIF('10-agents-referral-commission-p'!G2:G146,"Fail")-COUNTIF('10-agents-referral-commission-p'!G2:G146,"Blocked")-COUNTIF('10-agents-referral-commission-p'!G2:G146,"NA")
A12: 11-admin-users-settings-cms-reports | B12: 132 | C12: 0 | D12: 65 | E12: 64 | F12: 3 | G12: =COUNTIF('11-admin-users-settings-cms-rep'!G2:G133,"Pass") | H12: =COUNTIF('11-admin-users-settings-cms-rep'!G2:G133,"Fail") | I12: =COUNTIF('11-admin-users-settings-cms-rep'!G2:G133,"Blocked") | J12: =B12-COUNTIF('11-admin-users-settings-cms-rep'!G2:G133,"Pass")-COUNTIF('11-admin-users-settings-cms-rep'!G2:G133,"Fail")-COUNTIF('11-admin-users-settings-cms-rep'!G2:G133,"Blocked")-COUNTIF('11-admin-users-settings-cms-rep'!G2:G133,"NA")
A13: 12-security-and-nonfunctional | B13: 126 | C13: 7 | D13: 52 | E13: 55 | F13: 12 | G13: =COUNTIF('12-security-and-nonfunctional'!G2:G127,"Pass") | H13: =COUNTIF('12-security-and-nonfunctional'!G2:G127,"Fail") | I13: =COUNTIF('12-security-and-nonfunctional'!G2:G127,"Blocked") | J13: =B13-COUNTIF('12-security-and-nonfunctional'!G2:G127,"Pass")-COUNTIF('12-security-and-nonfunctional'!G2:G127,"Fail")-COUNTIF('12-security-and-nonfunctional'!G2:G127,"Blocked")-COUNTIF('12-security-and-nonfunctional'!G2:G127,"NA")
A14: 13-end-to-end-journeys | B14: 51 | C14: 2 | D14: 37 | E14: 12 | F14: 0 | G14: =COUNTIF('13-end-to-end-journeys'!G2:G52,"Pass") | H14: =COUNTIF('13-end-to-end-journeys'!G2:G52,"Fail") | I14: =COUNTIF('13-end-to-end-journeys'!G2:G52,"Blocked") | J14: =B14-COUNTIF('13-end-to-end-journeys'!G2:G52,"Pass")-COUNTIF('13-end-to-end-journeys'!G2:G52,"Fail")-COUNTIF('13-end-to-end-journeys'!G2:G52,"Blocked")-COUNTIF('13-end-to-end-journeys'!G2:G52,"NA")
A15: 14-api-authorization-matrix | B15: 289 | C15: 12 | D15: 171 | E15: 106 | F15: 0 | G15: =COUNTIF('14-api-authorization-matrix'!G2:G290,"Pass") | H15: =COUNTIF('14-api-authorization-matrix'!G2:G290,"Fail") | I15: =COUNTIF('14-api-authorization-matrix'!G2:G290,"Blocked") | J15: =B15-COUNTIF('14-api-authorization-matrix'!G2:G290,"Pass")-COUNTIF('14-api-authorization-matrix'!G2:G290,"Fail")-COUNTIF('14-api-authorization-matrix'!G2:G290,"Blocked")-COUNTIF('14-api-authorization-matrix'!G2:G290,"NA")
A16: 15-agent-profile-kyc-bank | B16: 204 | C16: 3 | D16: 76 | E16: 111 | F16: 14 | G16: =COUNTIF('15-agent-profile-kyc-bank'!G2:G205,"Pass") | H16: =COUNTIF('15-agent-profile-kyc-bank'!G2:G205,"Fail") | I16: =COUNTIF('15-agent-profile-kyc-bank'!G2:G205,"Blocked") | J16: =B16-COUNTIF('15-agent-profile-kyc-bank'!G2:G205,"Pass")-COUNTIF('15-agent-profile-kyc-bank'!G2:G205,"Fail")-COUNTIF('15-agent-profile-kyc-bank'!G2:G205,"Blocked")-COUNTIF('15-agent-profile-kyc-bank'!G2:G205,"NA")
A17: 16-agent-own-purchase | B17: 40 | C17: 5 | D17: 18 | E17: 17 | F17: 0 | G17: =COUNTIF('16-agent-own-purchase'!G2:G41,"Pass") | H17: =COUNTIF('16-agent-own-purchase'!G2:G41,"Fail") | I17: =COUNTIF('16-agent-own-purchase'!G2:G41,"Blocked") | J17: =B17-COUNTIF('16-agent-own-purchase'!G2:G41,"Pass")-COUNTIF('16-agent-own-purchase'!G2:G41,"Fail")-COUNTIF('16-agent-own-purchase'!G2:G41,"Blocked")-COUNTIF('16-agent-own-purchase'!G2:G41,"NA")
A18: TOTAL | B18: =SUM(B2:B17) | C18: =SUM(C2:C17) | D18: =SUM(D2:D17) | E18: =SUM(E2:E17) | F18: =SUM(F2:F17) | G18: =SUM(G2:G17) | H18: =SUM(H2:H17) | I18: =SUM(I2:I17) | J18: =SUM(J2:J17)

Sheet All Cases
A1: Test Case ID | B1: Module | C1: Section | D1: Priority | E1: Scenario | F1: Expected Result | G1: Status | H1: Tester | I1: Date | J1: Bug / Ticket | K1: Notes
A2: AUTH-001 | B2: 01-auth-and-access | C2: A. Registration – Step 1: Send email OTP (`/register`) | D2: P1 | E2: Enter a new valid email, click Send OTP | F2: OTP mail received, UI moves to OTP step, message "OTP sent successfully"
A3: AUTH-002 | B3: 01-auth-and-access | C3: A. Registration – Step 1: Send email OTP (`/register`) | D3: P1 | E3: Email already registered | F3: Error "An account with this email address already exists" (409)
A4: AUTH-003 | B4: 01-auth-and-access | C4: A. Registration – Step 1: Send email OTP (`/register`) | D4: P1 | E4: Empty email | F4: "Email is required"
A5: AUTH-004 | B5: 01-auth-and-access | C5: A. Registration – Step 1: Send email OTP (`/register`) | D5: P1 | E5: Email `abc` (no @) | F5: "Please enter a valid email address"
A6: AUTH-005 | B6: 01-auth-and-access | C6: A. Registration – Step 1: Send email OTP (`/register`) | D6: P2 | E6: Email `abc@` | F6: Invalid email error
A7: AUTH-006 | B7: 01-auth-and-access | C7: A. Registration – Step 1: Send email OTP (`/register`) | D7: P2 | E7: Email `@gmail.com` | F7: Invalid email error
A8: AUTH-007 | B8: 01-auth-and-access | C8: A. Registration – Step 1: Send email OTP (`/register`) | D8: P2 | E8: Email `a b@gmail.com` (space inside) | F8: Invalid email error
A9: AUTH-008 | B9: 01-auth-and-access | C9: A. Registration – Step 1: Send email OTP (`/register`) | D9: P2 | E9: Email with leading/trailing spaces ` a@b.com ` | F9: Trimmed, accepted
A10: AUTH-009 | B10: 01-auth-and-access | C10: A. Registration – Step 1: Send email OTP (`/register`) | D10: P2 | E10: Email in UPPER case `TEST@MAIL.COM` | F10: Lower-cased, same account as `test@mail.com`
A11: AUTH-010 | B11: 01-auth-and-access | C11: A. Registration – Step 1: Send email OTP (`/register`) | D11: P2 | E11: Register `Test@Mail.com` when `test@mail.com` exists | F11: Rejected as duplicate
A12: AUTH-011 | B12: 01-auth-and-access | C12: A. Registration – Step 1: Send email OTP (`/register`) | D12: P1 | E12: Click Send OTP twice within 60 s | F12: Second call blocked: "Please wait N second(s)…" (429)
A13: AUTH-012 | B13: 01-auth-and-access | C13: A. Registration – Step 1: Send email OTP (`/register`) | D13: P2 | E13: Countdown shown on resend button counts down 60→0 | F13: Button disabled until 0, then enabled
... A1787: CMP-015 | B1787: 12-security-and-nonfunctional | C1787: I. Compatibility & accessibility | D1787: P3 | E1787: Dev-tool hidden pane duplicate Suspense `div#S:0` in in-app browser | F1787: Known test artifact, not a bug
A1788: E2E-001 | B1788: 13-end-to-end-journeys | D1788: P1 | E1788: **Setup chain:** GST rate → HSN → Category → Brand → Unit → Attribute (Colour, Size) → Product (gender men) → Item (SKU, base ₹1000, opening stock) → Generate variants (2 colours × 3 sizes) → set prices → activate | F1788: Product visible on storefront with correct colour/size combos, per-row stock = opening stock, opening-stock PO `RECEIVED` under "Opening Stock" vendor, ledger PURCHASE rows
A1789: E2E-002 | B1789: 13-end-to-end-journeys | D1789: P1 | E1789: **Gender "Not applicable" product:** create electronics-type product with gender `Not applicable` end-to-end | F1789: Saves, appears in listing without gender filter, hidden under gender filter, no size chart error, header menu/size-chart pages still load
A1790: E2E-003 | B1790: 13-end-to-end-journeys | D1790: P1 | E1790: **Guest purchase (COD, Tamil Nadu):** browse → add 2 → cart → guest checkout → place | F1790: Shipping ₹0, order `confirmed`, stock −2, shadow account, success page, admin sees it in Confirmed
A1791: E2E-004 | B1791: 13-end-to-end-journeys | D1791: P1 | E1791: **Guest purchase (COD, Kerala):** same | F1791: Shipping ₹80, total correct
A1792: E2E-005 | B1792: 13-end-to-end-journeys | D1792: P1 | E1792: **Registered purchase (Razorpay success):** register via OTP → address → coupon → pay with test card | F1792: Order `confirmed`+`paid`, amount = total, stock −N, coupon usage +1, invoice downloadable
A1793: E2E-006 | B1793: 13-end-to-end-journeys | D1793: P1 | E1793: **Payment failure then retry:** fail card → retry success | F1793: One order only, stock deducted once
A1794: E2E-007 | B1794: 13-end-to-end-journeys | D1794: P1 | E1794: **Full fulfilment (staff delivery):** confirm → processing → packed → assign staff → staff accepts → out for delivery → delivered | F1794: Timeline complete on both sides; `delivered_at` set; commission clock starts (if referred); COD marked paid
A1795: E2E-008 | B1795: 13-end-to-end-journeys | D1795: P1 | E1795: **Full fulfilment (courier):** pack → ship with `EE123456789IN` → mark delivered | F1795: Tracking link on customer page works
A1796: E2E-009 | B1796: 13-end-to-end-journeys | D1796: P1 | E1796: **Customer cancel before packing:** place → cancel (reason) | F1796: Stock restored once, paid order refunded, commission cancelled
A1797: E2E-010 | B1797: 13-end-to-end-journeys | D1797: P1 | E1797: **Admin cancel after shipping** | F1797: Allowed; stock restored; refund; commission reversed
A1798: E2E-011 | B1798: 13-end-to-end-journeys | D1798: P1 | E1798: **Return happy path:** delivered → request within 3 days with video → review → approve → pickup → picked up → received → refund → refunded → close | F1798: Each customer-visible status; stock +qty on received; payment `refunded`/`partial_refund`; commission reversed for those items
A1799: E2E-012 | B1799: 13-end-to-end-journeys | D1799: P1 | E1799: **Return window expiry:** delivered 4 days ago | F1799: Request rejected with "return period… expired"
... A1830: E2E-043 | B1830: 13-end-to-end-journeys | D1830: P1 | E1830: **Rollback drill:** restore DB backup, confirm app boots and orders intact | F1830: Pass
A1831: API-001 | B1831: 14-api-authorization-matrix | C1831: Admin APIs | D1831: P1 | E1831: Call GET /api/admin/agent-orders as GUEST / CUSTOMER / AGENT / STAFF / ADMIN | F1831: Guest=401 | Customer=403 | Agent=403 | Staff=200 | Admin=200
A1832: API-002 | B1832: 14-api-authorization-matrix | C1832: Admin APIs | D1832: P1 | E1832: Call POST /api/admin/agent-payouts/[uuid]/approve as GUEST / CUSTOMER / AGENT / STAFF / ADMIN | F1832: Guest=401 | Customer=403 | Agent=403 | Staff=403 | Admin=200
A1833: API-003 | B1833: 14-api-authorization-matrix | C1833: Admin APIs | D1833: P1 | E1833: Call GET /api/admin/agent-payouts/[uuid]/destination as GUEST / CUSTOMER / AGENT / STAFF / ADMIN | F1833: Guest=401 | Customer=403 | Agent=403 | Staff=403 | Admin=200
A1834: API-004 | B1834: 14-api-authorization-matrix | C1834: Admin APIs | D1834: P1 | E1834: Call POST /api/admin/agent-payouts/[uuid]/mark-paid as GUEST / CUSTOMER / AGENT / STAFF / ADMIN | F1834: Guest=401 | Customer=403 | Agent=403 | Staff=403 | Admin=200
A1835: API-005 | B1835: 14-api-authorization-matrix | C1835: Admin APIs | D1835: P1 | E1835: Call POST /api/admin/agent-payouts/[uuid]/reject as GUEST / CUSTOMER / AGENT / STAFF / ADMIN | F1835: Guest=401 | Customer=403 | Agent=403 | Staff=403 | Admin=200
A1836: API-006 | B1836: 14-api-authorization-matrix | C1836: Admin APIs | D1836: P1 | E1836: Call GET /api/admin/agent-payouts as GUEST / CUSTOMER / AGENT / STAFF / ADMIN | F1836: Guest=401 | Customer=403 | Agent=403 | Staff=200 | Admin=200
A1837: API-007 | B1837: 14-api-authorization-matrix | C1837: Admin APIs | D1837: P1 | E1837: Call GET /api/admin/agents/[uuid]/document/[kind] as GUEST / CUSTOMER / AGENT / STAFF / ADMIN | F1837: Guest=401 | Customer=403 | Agent=403 | Staff=200 | Admin=200
A1838: API-008 | B1838: 14-api-authorization-matrix | C1838: Admin APIs | D1838: P1 | E1838: Call GET /api/admin/agents/[uuid]/profile as GUEST / CUSTOMER / AGENT / STAFF / ADMIN | F1838: Guest=401 | Customer=403 | Agent=403 | Staff=200 | Admin=200
A1839: API-009 | B1839: 14-api-authorization-matrix | C1839: Admin APIs | D1839: P1 | E1839: Call GET /api/admin/agents/[uuid]/purchases as GUEST / CUSTOMER / AGENT / STAFF / ADMIN | F1839: Guest=401 | Customer=403 | Agent=403 | Staff=200 | Admin=200
A1840: API-010 | B1840: 14-api-authorization-matrix | C1840: Admin APIs | D1840: P1 | E1840: Call POST /api/admin/agents/[uuid]/review as GUEST / CUSTOMER / AGENT / STAFF / ADMIN | F1840: Guest=401 | Customer=403 | Agent=403 | Staff=403 | Admin=200
A1841: API-011 | B1841: 14-api-authorization-matrix | C1841: Admin APIs | D1841: P1 | E1841: Call GET/PUT/PATCH /api/admin/agents/[uuid] as GUEST / CUSTOMER / AGENT / STAFF / ADMIN | F1841: Guest=401 | Customer=403 | Agent=403 | Staff=403 | Admin=200
A1842: API-012 | B1842: 14-api-authorization-matrix | C1842: Admin APIs | D1842: P1 | E1842: Call GET /api/admin/agents/options as GUEST / CUSTOMER / AGENT / STAFF / ADMIN | F1842: Guest=401 | Customer=403 | Agent=403 | Staff=200 | Admin=200
... A2323: APF-204 | B2323: 15-agent-profile-kyc-bank | C2323: J. Responsive & UX | D2323: P2 | E2323: [Int] Two tabs editing different steps | F2323: Last write per field wins; no wipe of other tab's data (blank = unchanged)
...

Sheet 01-auth-and-access
A1: Test Case ID | B1: Module | C1: Section | D1: Priority | E1: Scenario | F1: Expected Result | G1: Status | H1: Tester | I1: Date | J1: Bug / Ticket | K1: Notes
A2: AUTH-001 | B2: 01-auth-and-access | C2: A. Registration – Step 1: Send email OTP (`/register`) | D2: P1 | E2: Enter a new valid email, click Send OTP | F2: OTP mail received, UI moves to OTP step, message "OTP sent successfully"
A3: AUTH-002 | B3: 01-auth-and-access | C3: A. Registration – Step 1: Send email OTP (`/register`) | D3: P1 | E3: Email already registered | F3: Error "An account with this email address already exists" (409)
A4: AUTH-003 | B4: 01-auth-and-access | C4: A. Registration – Step 1: Send email OTP (`/register`) | D4: P1 | E4: Empty email | F4: "Email is required"
A5: AUTH-004 | B5: 01-auth-and-access | C5: A. Registration – Step 1: Send email OTP (`/register`) | D5: P1 | E5: Email `abc` (no @) | F5: "Please enter a valid email address"
A6: AUTH-005 | B6: 01-auth-and-access | C6: A. Registration – Step 1: Send email OTP (`/register`) | D6: P2 | E6: Email `abc@` | F6: Invalid email error
A7: AUTH-006 | B7: 01-auth-and-access | C7: A. Registration – Step 1: Send email OTP (`/register`) | D7: P2 | E7: Email `@gmail.com` | F7: Invalid email error
A8: AUTH-007 | B8: 01-auth-and-access | C8: A. Registration – Step 1: Send email OTP (`/register`) | D8: P2 | E8: Email `a b@gmail.com` (space inside) | F8: Invalid email error
A9: AUTH-008 | B9: 01-auth-and-access | C9: A. Registration – Step 1: Send email OTP (`/register`) | D9: P2 | E9: Email with leading/trailing spaces ` a@b.com ` | F9: Trimmed, accepted
A10: AUTH-009 | B10: 01-auth-and-access | C10: A. Registration – Step 1: Send email OTP (`/register`) | D10: P2 | E10: Email in UPPER case `TEST@MAIL.COM` | F10: Lower-cased, same account as `test@mail.com`
A11: AUTH-010 | B11: 01-auth-and-access | C11: A. Registration – Step 1: Send email OTP (`/register`) | D11: P2 | E11: Register `Test@Mail.com` when `test@mail.com` exists | F11: Rejected as duplicate
A12: AUTH-011 | B12: 01-auth-and-access | C12: A. Registration – Step 1: Send email OTP (`/register`) | D12: P1 | E12: Click Send OTP twice within 60 s | F12: Second call blocked: "Please wait N second(s)…" (429)
A13: AUTH-012 | B13: 01-auth-and-access | C13: A. Registration – Step 1: Send email OTP (`/register`) | D13: P2 | E13: Countdown shown on resend button counts down 60→0 | F13: Button disabled until 0, then enabled
... A166: AUTH-165 | B166: 01-auth-and-access | C166: H. Admin & agent login pages | D166: P2 | E166: Delivery staff login | F166: Lands where intended; only delivery APIs usable

Sheet 02-storefront-catalog
A1: Test Case ID | B1: Module | C1: Section | D1: Priority | E1: Scenario | F1: Expected Result | G1: Status | H1: Tester | I1: Date | J1: Bug / Ticket | K1: Notes
A2: SF-001 | B2: 02-storefront-catalog | C2: A. Home page (`/`) | D2: P1 | E2: Open `/` as guest | F2: Page loads, no console errors, header + footer present
A3: SF-002 | B3: 02-storefront-catalog | C3: A. Home page (`/`) | D3: P1 | E3: Banner carousel shows active banners only | F3: Inactive / expired / not-yet-started banners hidden
A4: SF-003 | B4: 02-storefront-catalog | C4: A. Home page (`/`) | D4: P2 | E4: Banner with `startsAt` in future | F4: Not displayed until start time
A5: SF-004 | B5: 02-storefront-catalog | C5: A. Home page (`/`) | D5: P2 | E5: Banner with `endsAt` in past | F5: Not displayed
A6: SF-005 | B6: 02-storefront-catalog | C6: A. Home page (`/`) | D6: P2 | E6: Banner `sortOrder` 0 vs 5 | F6: Lower sort order first
A7: SF-006 | B7: 02-storefront-catalog | C7: A. Home page (`/`) | D7: P2 | E7: Click banner with `linkUrl` | F7: Navigates to that link
A8: SF-007 | B8: 02-storefront-catalog | C8: A. Home page (`/`) | D8: P2 | E8: Banner without `linkUrl` | F8: Not clickable / no broken link
A9: SF-008 | B9: 02-storefront-catalog | C9: A. Home page (`/`) | D9: P2 | E9: Video banner (reels) plays, muted autoplay, has thumbnail while loading | F9: Works; no layout shift
A10: SF-009 | B10: 02-storefront-catalog | C10: A. Home page (`/`) | D10: P2 | E10: Banner badge label / subtitle / price text shown when set, hidden when empty | F10: Matches admin data
A11: SF-010 | B11: 02-storefront-catalog | C11: A. Home page (`/`) | D11: P2 | E11: Banner positions: each home position renders only its own banners | F11: Correct slot
A12: SF-011 | B12: 02-storefront-catalog | C12: A. Home page (`/`) | D12: P1 | E12: Featured / new-arrival sections list correct products | F12: Matches admin flags
A13: SF-012 | B13: 02-storefront-catalog | C13: A. Home page (`/`) | D13: P2 | E13: Product card shows image, name, price, discount badge | F13: Values match admin
... A193: SF-192 | B193: 02-storefront-catalog | C193: I. Responsive, SEO, performance (storefront) | D193: P2 | E193: 404 page and 500 error page | F193: Friendly, branded, link home

Sheet 03-cart-wishlist
A1: Test Case ID | B1: Module | C1: Section | D1: Priority | E1: Scenario | F1: Expected Result | G1: Status | H1: Tester | I1: Date | J1: Bug / Ticket | K1: Notes
A2: CART-001 | B2: 03-cart-wishlist | C2: A. Add to cart | D2: P1 | E2: Guest adds in-stock item qty 1 | F2: Added, cart count 1, guest cookie set
A3: CART-002 | B3: 03-cart-wishlist | C3: A. Add to cart | D3: P1 | E3: Logged-in adds in-stock item | F3: Added to DB cart for user
A4: CART-003 | B4: 03-cart-wishlist | C4: A. Add to cart | D4: P1 | E4: Add same unit-price twice (qty 1 + 1) | F4: One line, qty 2
A5: CART-004 | B5: 03-cart-wishlist | C5: A. Add to cart | D5: P1 | E5: Add different size of same product | F5: Separate line
A6: CART-005 | B6: 03-cart-wishlist | C6: A. Add to cart | D6: P1 | E6: Add different colour of same product | F6: Separate line
A7: CART-006 | B7: 03-cart-wishlist | C7: A. Add to cart | D7: P1 | E7: Qty = available stock | F7: Accepted
A8: CART-007 | B8: 03-cart-wishlist | C8: A. Add to cart | D8: P1 | E8: Qty = stock + 1 | F8: "Only N left for this colour and size combination"
A9: CART-008 | B9: 03-cart-wishlist | C9: A. Add to cart | D9: P1 | E9: Existing cart qty 3 + add 3 when stock 5 | F9: Rejected/capped (combined > stock) – verify no overselling
A10: CART-009 | B10: 03-cart-wishlist | C10: A. Add to cart | D10: P1 | E10: Stock 0 for chosen Colour/Size but other size has stock | F10: "This colour and size combination is out of stock"
A11: CART-010 | B11: 03-cart-wishlist | C11: A. Add to cart | D11: P1 | E11: Variant flagged `out_of_stock` by admin but inventory>0 | F11: Rejected
A12: CART-011 | B12: 03-cart-wishlist | C12: A. Add to cart | D12: P1 | E12: Inactive unit price | F12: "Product variant is unavailable"
A13: CART-012 | B13: 03-cart-wishlist | C13: A. Add to cart | D13: P1 | E13: Inactive variant | F13: Same
... A98: WL-019 | B98: 03-cart-wishlist | C98: E. Wishlist (`/wishlist`, logged-in only) | D98: P2 | E98: Admin views customer cart | F98: Matches

Sheet 04-checkout-payment-orders
A1: Test Case ID | B1: Module | C1: Section | D1: Priority | E1: Scenario | F1: Expected Result | G1: Status | H1: Tester | I1: Date | J1: Bug / Ticket | K1: Notes
A2: CO-001 | B2: 04-checkout-payment-orders | C2: A. Checkout entry & address step (`/checkout`, `/checkout/address`) | D2: P1 | E2: Empty cart → open `/checkout` | F2: Redirect to cart / "cart is empty"
A3: CO-002 | B3: 04-checkout-payment-orders | C3: A. Checkout entry & address step (`/checkout`, `/checkout/address`) | D3: P1 | E3: Logged-in with saved addresses | F3: List shown, default pre-selected
A4: CO-003 | B4: 04-checkout-payment-orders | C4: A. Checkout entry & address step (`/checkout`, `/checkout/address`) | D4: P1 | E4: Logged-in without address | F4: Add-address form shown
A5: CO-004 | B5: 04-checkout-payment-orders | C5: A. Checkout entry & address step (`/checkout`, `/checkout/address`) | D5: P1 | E5: Add address – all valid | F5: Saved, selectable
A6: CO-005 | B6: 04-checkout-payment-orders | C6: A. Checkout entry & address step (`/checkout`, `/checkout/address`) | D6: P1 | E6: Full name empty | F6: "Full name is required"
A7: CO-006 | B7: 04-checkout-payment-orders | C7: A. Checkout entry & address step (`/checkout`, `/checkout/address`) | D7: P2 | E7: Full name 150 / 151 chars | F7: 150 ok / 151 "cannot exceed 150"
A8: CO-007 | B8: 04-checkout-payment-orders | C8: A. Checkout entry & address step (`/checkout`, `/checkout/address`) | D8: P1 | E8: Phone `9876543210` | F8: Stored `+919876543210`
A9: CO-008 | B9: 04-checkout-payment-orders | C9: A. Checkout entry & address step (`/checkout`, `/checkout/address`) | D9: P1 | E9: Phone `1234567890`, `98765`, `+4498…` | F9: Indian-number error message
A10: CO-009 | B10: 04-checkout-payment-orders | C10: A. Checkout entry & address step (`/checkout`, `/checkout/address`) | D10: P1 | E10: Address line 1 empty | F10: "Address line 1 is required"
A11: CO-010 | B11: 04-checkout-payment-orders | C11: A. Checkout entry & address step (`/checkout`, `/checkout/address`) | D11: P2 | E11: Line 1 255 / 256 chars | F11: ok / error
A12: CO-011 | B12: 04-checkout-payment-orders | C12: A. Checkout entry & address step (`/checkout`, `/checkout/address`) | D12: P2 | E12: Line 2 optional; 255 / 256 | F12: ok / error
A13: CO-012 | B13: 04-checkout-payment-orders | C13: A. Checkout entry & address step (`/checkout`, `/checkout/address`) | D13: P2 | E13: Landmark optional; 150 / 151 | F13: ok / error
... A154: CO-153 | B154: 04-checkout-payment-orders | C154: H. Legacy / alternate order APIs (security) | D154: P2 | E154: Pass UUID of another user's order to `/api/customer/orders/{uuid}` | F154: 404 Order not found

Sheet 05-customer-account
A1: Test Case ID | B1: Module | C1: Section | D1: Priority | E1: Scenario | F1: Expected Result | G1: Status | H1: Tester | I1: Date | J1: Bug / Ticket | K1: Notes
A2: ACC-001 | B2: 05-customer-account | C2: A. Profile (`/profile`) | D2: P1 | E2: Open profile logged-in | F2: Name, email (read-only), phone, DOB, gender shown
A3: ACC-002 | B3: 05-customer-account | C3: A. Profile (`/profile`) | D3: P1 | E3: Update name valid | F3: Saved, header name updates
A4: ACC-003 | B4: 05-customer-account | C4: A. Profile (`/profile`) | D4: P1 | E4: Name empty | F4: "Name cannot be empty"
A5: ACC-004 | B5: 05-customer-account | C5: A. Profile (`/profile`) | D5: P2 | E5: Name 255 / 256 chars | F5: ok / "cannot exceed 255 characters"
A6: ACC-005 | B6: 05-customer-account | C6: A. Profile (`/profile`) | D6: P1 | E6: DOB past date | F6: Saved
A7: ACC-006 | B7: 05-customer-account | C7: A. Profile (`/profile`) | D7: P1 | E7: DOB today | F7: Saved (≤ end of today)
A8: ACC-007 | B8: 05-customer-account | C8: A. Profile (`/profile`) | D8: P1 | E8: DOB tomorrow | F8: "Date of birth cannot be a future date"
A9: ACC-008 | B9: 05-customer-account | C9: A. Profile (`/profile`) | D9: P2 | E9: DOB invalid string `31-02-2020` / `abc` | F9: Rejected
A10: ACC-009 | B10: 05-customer-account | C10: A. Profile (`/profile`) | D10: P2 | E10: DOB cleared (null) | F10: Allowed
A11: ACC-010 | B11: 05-customer-account | C11: A. Profile (`/profile`) | D11: P2 | E11: Gender male / female / other / null | F11: Accepted
A12: ACC-011 | B12: 05-customer-account | C12: A. Profile (`/profile`) | D12: P2 | E12: Gender `unknown` | F12: Rejected
A13: ACC-012 | B13: 05-customer-account | C13: A. Profile (`/profile`) | D13: P1 | E13: WhatsApp toggle ON + valid number `9876543210` | F13: Stored `+919876543210`
... A148: ACC-147 | B148: 05-customer-account | C148: H. Invoice (`/invoice/[uuid]`) | D148: P2 | E148: Company logo missing | F148: Placeholder, no broken image

Sheet 06-admin-catalog-masters
A1: Test Case ID | B1: Module | C1: Section | D1: Priority | E1: Scenario | F1: Expected Result | G1: Status | H1: Tester | I1: Date | J1: Bug / Ticket | K1: Notes
A2: ADM-C-001 | B2: 06-admin-catalog-masters | C2: A. Categories (`/admin/dashboard/categories`) | D2: P1 | E2: Create valid (name, code `MEN_SHIRTS`) | F2: Saved, appears in list
A3: ADM-C-002 | B3: 06-admin-catalog-masters | C3: A. Categories (`/admin/dashboard/categories`) | D3: P1 | E3: Name empty | F3: "Category name is required"
A4: ADM-C-003 | B4: 06-admin-catalog-masters | C4: A. Categories (`/admin/dashboard/categories`) | D4: P2 | E4: Name 150 / 151 chars | F4: ok / "cannot exceed 150"
A5: ADM-C-004 | B5: 06-admin-catalog-masters | C5: A. Categories (`/admin/dashboard/categories`) | D5: P1 | E5: Code empty | F5: "Category code is required"
A6: ADM-C-005 | B6: 06-admin-catalog-masters | C6: A. Categories (`/admin/dashboard/categories`) | D6: P1 | E6: Code with space / hyphen / `@` (`MEN-SHIRTS`) | F6: "Category code can only contain letters, numbers, and underscores"
A7: ADM-C-006 | B7: 06-admin-catalog-masters | C7: A. Categories (`/admin/dashboard/categories`) | D7: P2 | E7: Code 170 / 171 chars | F7: ok / error
A8: ADM-C-007 | B8: 06-admin-catalog-masters | C8: A. Categories (`/admin/dashboard/categories`) | D8: P1 | E8: Duplicate name | F8: "A category with name '…' already exists"
A9: ADM-C-008 | B9: 06-admin-catalog-masters | C9: A. Categories (`/admin/dashboard/categories`) | D9: P1 | E9: Duplicate code (slug) | F9: "A category with slug '…' already exists"
A10: ADM-C-009 | B10: 06-admin-catalog-masters | C10: A. Categories (`/admin/dashboard/categories`) | D10: P2 | E10: Duplicate with different case (`men` vs `MEN`) | F10: Verify rule (conflict or allowed) – record
A11: ADM-C-010 | B11: 06-admin-catalog-masters | C11: A. Categories (`/admin/dashboard/categories`) | D11: P2 | E11: Description 2000 / 2001 | F11: ok / error
A12: ADM-C-011 | B12: 06-admin-catalog-masters | C12: A. Categories (`/admin/dashboard/categories`) | D12: P2 | E12: Icon path 500 / 501 | F12: ok / error
A13: ADM-C-012 | B13: 06-admin-catalog-masters | C13: A. Categories (`/admin/dashboard/categories`) | D13: P2 | E13: Sort order 0, 100 / -1, 101, 1.5 | F13: ok / "cannot be negative", "cannot exceed 100", "must be an integer"
... A239: ADM-UPL-011 | B239: 06-admin-catalog-masters | C239: L. Image / file upload (shared) | D239: P2 | E239: Files persist after redeploy (`UPLOAD_DIR` outside deploy dir) | F239: Yes

Sheet 07-offers-coupons-pricing
A1: Test Case ID | B1: Module | C1: Section | D1: Priority | E1: Scenario | F1: Expected Result | G1: Status | H1: Tester | I1: Date | J1: Bug / Ticket | K1: Notes
A2: OFR-001 | B2: 07-offers-coupons-pricing | C2: A. Admin: create / edit offer (`/admin/dashboard/offers`) | D2: P1 | E2: Valid percentage 10% product-level, 1 product, dates valid | F2: Saved, status computed correctly
A3: OFR-002 | B3: 07-offers-coupons-pricing | C3: A. Admin: create / edit offer (`/admin/dashboard/offers`) | D3: P1 | E3: Name empty / 151 chars | F3: "Offer name is required" / max error
A4: OFR-003 | B4: 07-offers-coupons-pricing | C4: A. Admin: create / edit offer (`/admin/dashboard/offers`) | D4: P1 | E4: Level not selected | F4: "Select an offer level"
A5: OFR-004 | B5: 07-offers-coupons-pricing | C5: A. Admin: create / edit offer (`/admin/dashboard/offers`) | D5: P1 | E5: Type not selected | F5: "Select an offer type"
A6: OFR-005 | B6: 07-offers-coupons-pricing | C6: A. Admin: create / edit offer (`/admin/dashboard/offers`) | D6: P1 | E6: Percentage = 0 | F6: "Discount percentage must be greater than 0"
A7: OFR-006 | B7: 07-offers-coupons-pricing | C7: A. Admin: create / edit offer (`/admin/dashboard/offers`) | D7: P1 | E7: Percentage = 100 | F7: Accepted
A8: OFR-007 | B8: 07-offers-coupons-pricing | C8: A. Admin: create / edit offer (`/admin/dashboard/offers`) | D8: P1 | E8: Percentage = 100.01 / 101 | F8: "Discount percentage cannot exceed 100%"
A9: OFR-008 | B9: 07-offers-coupons-pricing | C9: A. Admin: create / edit offer (`/admin/dashboard/offers`) | D9: P1 | E9: Percentage negative | F9: "Discount value cannot be negative"
A10: OFR-009 | B10: 07-offers-coupons-pricing | C10: A. Admin: create / edit offer (`/admin/dashboard/offers`) | D10: P1 | E10: Flat = 0 | F10: "Discount amount must be greater than 0"
A11: OFR-010 | B11: 07-offers-coupons-pricing | C11: A. Admin: create / edit offer (`/admin/dashboard/offers`) | D11: P1 | E11: Special price = 0 | F11: "Special offer price must be greater than 0"
A12: OFR-011 | B12: 07-offers-coupons-pricing | C12: A. Admin: create / edit offer (`/admin/dashboard/offers`) | D12: P1 | E12: BXGY without buy qty | F12: "Buy quantity is required and must be at least 1"
A13: OFR-012 | B13: 07-offers-coupons-pricing | C13: A. Admin: create / edit offer (`/admin/dashboard/offers`) | D13: P1 | E13: BXGY without get qty | F13: "Get quantity is required and must be at least 1"
... A124: PRC-010 | B124: 07-offers-coupons-pricing | C124: H. Totals & rounding across the funnel | D124: P2 | E124: Price history entry on each price change | F124: Recorded with old/new, timestamp

Sheet 08-admin-orders-delivery-return
A1: Test Case ID | B1: Module | C1: Section | D1: Priority | E1: Scenario | F1: Expected Result | G1: Status | H1: Tester | I1: Date | J1: Bug / Ticket | K1: Notes
A2: AO-001 | B2: 08-admin-orders-delivery-returns | C2: A. Admin order lists (`/admin/dashboard/orders/*`) | D2: P1 | E2: All Orders page loads with totals | F2: Count equals `/orders/count`
A3: AO-002 | B3: 08-admin-orders-delivery-returns | C3: A. Admin order lists (`/admin/dashboard/orders/*`) | D3: P1 | E3: Each status page (pending, confirmed, processing, packed, shipped, out-for-delivery, delivered, cancelled, returned) lists only that status | F3: Correct
A4: AO-003 | B4: 08-admin-orders-delivery-returns | C4: A. Admin order lists (`/admin/dashboard/orders/*`) | D4: P1 | E4: Replacement & Returns pages list requests | F4: Correct
A5: AO-004 | B5: 08-admin-orders-delivery-returns | C5: A. Admin order lists (`/admin/dashboard/orders/*`) | D5: P2 | E5: Search by order number partial | F5: Match
A6: AO-005 | B6: 08-admin-orders-delivery-returns | C6: A. Admin order lists (`/admin/dashboard/orders/*`) | D6: P2 | E6: Search by customer name/email/phone (if supported) | F6: Match
A7: AO-006 | B7: 08-admin-orders-delivery-returns | C7: A. Admin order lists (`/admin/dashboard/orders/*`) | D7: P2 | E7: Filter by payment status paid/pending/failed/refunded/partial_refund | F7: Correct
A8: AO-007 | B8: 08-admin-orders-delivery-returns | C8: A. Admin order lists (`/admin/dashboard/orders/*`) | D8: P2 | E8: Filter by customer id (invalid UUID) | F8: "Invalid customerId UUID format"
A9: AO-008 | B9: 08-admin-orders-delivery-returns | C9: A. Admin order lists (`/admin/dashboard/orders/*`) | D9: P2 | E9: Sort by orderNumber, createdAt, placedAt, totalAmount, orderStatus, paymentStatus asc/desc | F9: Correct
A10: AO-009 | B10: 08-admin-orders-delivery-returns | C10: A. Admin order lists (`/admin/dashboard/orders/*`) | D10: P2 | E10: Invalid sort field | F10: Validation error
A11: AO-010 | B11: 08-admin-orders-delivery-returns | C11: A. Admin order lists (`/admin/dashboard/orders/*`) | D11: P2 | E11: pageSize 100 ok / 101 error / page 0 error | F11: per schema
A12: AO-011 | B12: 08-admin-orders-delivery-returns | C12: A. Admin order lists (`/admin/dashboard/orders/*`) | D12: P2 | E12: Sidebar badge counts match pages | F12: Equal
A13: AO-012 | B13: 08-admin-orders-delivery-returns | C13: A. Admin order lists (`/admin/dashboard/orders/*`) | D13: P2 | E13: Order detail: customer, addresses, items, payment, timeline, referral/agent block | F13: Complete
... A141: EQ-015 | B141: 08-admin-orders-delivery-returns | C141: I. Customers' enquiries: Contact messages & Bulk orders | D141: P2 | E141: XSS in message/product interest shown in admin | F141: Escaped

Sheet 09-inventory-purchases
A1: Test Case ID | B1: Module | C1: Section | D1: Priority | E1: Scenario | F1: Expected Result | G1: Status | H1: Tester | I1: Date | J1: Bug / Ticket | K1: Notes
A2: INV-001 | B2: 09-inventory-purchases | C2: A. Stock list (`/admin/dashboard/inventory/stock`, `/inventory`) | D2: P1 | E2: Stock list loads with product, colour, size, SKU, quantity | F2: Correct values
A3: INV-002 | B3: 09-inventory-purchases | C3: A. Stock list (`/admin/dashboard/inventory/stock`, `/inventory`) | D3: P1 | E3: Filter status in_stock / low_stock / out_of_stock | F3: Uses threshold from settings
A4: INV-003 | B4: 09-inventory-purchases | C4: A. Stock list (`/admin/dashboard/inventory/stock`, `/inventory`) | D4: P1 | E4: Low-stock boundary: qty == threshold | F4: Treated per rule (document: low or in-stock)
A5: INV-004 | B5: 09-inventory-purchases | C5: A. Stock list (`/admin/dashboard/inventory/stock`, `/inventory`) | D5: P1 | E5: Qty 0 → out_of_stock | F5: Yes
A6: INV-005 | B6: 09-inventory-purchases | C6: A. Stock list (`/admin/dashboard/inventory/stock`, `/inventory`) | D6: P2 | E6: Search by product/SKU/colour | F6: Match
A7: INV-006 | B7: 09-inventory-purchases | C7: A. Stock list (`/admin/dashboard/inventory/stock`, `/inventory`) | D7: P2 | E7: Filter by colour | F7: Correct
A8: INV-007 | B8: 09-inventory-purchases | C8: A. Stock list (`/admin/dashboard/inventory/stock`, `/inventory`) | D8: P2 | E8: Page / limit 100 ok / 101 error | F8: per schema
A9: INV-008 | B9: 09-inventory-purchases | C9: A. Stock list (`/admin/dashboard/inventory/stock`, `/inventory`) | D9: P2 | E9: Filter by `variantUnitPriceId` non-numeric / negative | F9: Validation error
A10: INV-009 | B10: 09-inventory-purchases | C10: A. Stock list (`/admin/dashboard/inventory/stock`, `/inventory`) | D10: P2 | E10: Dashboard cards (total SKUs, low, out, stock value) | F10: Match list math
A11: INV-010 | B11: 09-inventory-purchases | C11: A. Stock list (`/admin/dashboard/inventory/stock`, `/inventory`) | D11: P2 | E11: Settings: low-stock threshold 0, 100000 / -1, 100001, 1.5 | F11: ok / errors
A12: INV-011 | B12: 09-inventory-purchases | C12: A. Stock list (`/admin/dashboard/inventory/stock`, `/inventory`) | D12: P2 | E12: Changing threshold updates low-stock list immediately | F12: Yes
A13: INV-012 | B13: 09-inventory-purchases | C13: A. Stock list (`/admin/dashboard/inventory/stock`, `/inventory`) | D13: P2 | E13: Legacy `/api/inventory` list/low-stock/get by id; unknown id | F13: "Inventory item not found"
... A129: PO-050 | B129: 09-inventory-purchases | C129: G. Purchase orders (`/admin/dashboard/purchase-orders`) | D129: P2 | E129: Staff without purchase permission | F129: Hidden / 403

Sheet 10-agents-referral-commission-p
A1: Test Case ID | B1: Module | C1: Section | D1: Priority | E1: Scenario | F1: Expected Result | G1: Status | H1: Tester | I1: Date | J1: Bug / Ticket | K1: Notes
A2: AG-001 | B2: 10-agents-referral-commission-payout | C2: A. Agent management (admin: `/admin/dashboard/agents`) | D2: P1 | E2: Create agent: name, email, password, phone | F2: Agent role user + profile + auto code (e.g. AGT001)
A3: AG-002 | B3: 10-agents-referral-commission-payout | C3: A. Agent management (admin: `/admin/dashboard/agents`) | D3: P1 | E3: Name 1 char / empty / 151 | F3: "Name is required" (min 2) / max error
A4: AG-003 | B4: 10-agents-referral-commission-payout | C4: A. Agent management (admin: `/admin/dashboard/agents`) | D4: P1 | E4: Email invalid / 151 chars | F4: "Enter a valid email" / max
A5: AG-004 | B5: 10-agents-referral-commission-payout | C5: A. Agent management (admin: `/admin/dashboard/agents`) | D5: P1 | E5: Duplicate email | F5: "An account with this email address already exists"
A6: AG-005 | B6: 10-agents-referral-commission-payout | C6: A. Agent management (admin: `/admin/dashboard/agents`) | D6: P1 | E6: Phone `abc123`, 6 digits, 21 chars | F6: "Enter a valid phone number" (7–20 of digits,+,-,space)
A7: AG-006 | B7: 10-agents-referral-commission-payout | C7: A. Agent management (admin: `/admin/dashboard/agents`) | D7: P1 | E7: Duplicate phone | F7: "An account with this phone number already exists"
A8: AG-007 | B8: 10-agents-referral-commission-payout | C8: A. Agent management (admin: `/admin/dashboard/agents`) | D8: P1 | E8: Phone empty string | F8: Treated as none
A9: AG-008 | B9: 10-agents-referral-commission-payout | C9: A. Agent management (admin: `/admin/dashboard/agents`) | D9: P1 | E9: Password 7 / 8 / 100 / 101 chars | F9: error / ok / ok / error
A10: AG-009 | B10: 10-agents-referral-commission-payout | C10: A. Agent management (admin: `/admin/dashboard/agents`) | D10: P2 | E10: Notes 500 / 501 | F10: ok / error
A11: AG-010 | B11: 10-agents-referral-commission-payout | C11: A. Agent management (admin: `/admin/dashboard/agents`) | D11: P1 | E11: Edit agent name/phone/notes | F11: Saved
A12: AG-011 | B12: 10-agents-referral-commission-payout | C12: A. Agent management (admin: `/admin/dashboard/agents`) | D12: P1 | E12: Update with empty body | F12: "Nothing to update"
A13: AG-012 | B13: 10-agents-referral-commission-payout | C13: A. Agent management (admin: `/admin/dashboard/agents`) | D13: P1 | E13: Deactivate agent | F13: Cannot log in ("Your Sales Partner account is inactive…"); referral code no longer credits new orders
... A146: CRP-005 | B146: 10-agents-referral-commission-payout | C146: H. Reports (`/commission-reports`, `/agent-payouts`) | D146: P2 | E146: Reversed/clawback visible | F146: Flagged

Sheet 11-admin-users-settings-cms-rep
A1: Test Case ID | B1: Module | C1: Section | D1: Priority | E1: Scenario | F1: Expected Result | G1: Status | H1: Tester | I1: Date | J1: Bug / Ticket | K1: Notes
A2: ADM-CU-001 | B2: 11-admin-users-settings-cms-reports | C2: A. Customers (`/admin/dashboard/customers`) | D2: P1 | E2: List loads with name, email, phone, status, orders, last login | F2: Correct
A3: ADM-CU-002 | B3: 11-admin-users-settings-cms-reports | C3: A. Customers (`/admin/dashboard/customers`) | D3: P1 | E3: Search by name / email / phone | F3: Match
A4: ADM-CU-003 | B4: 11-admin-users-settings-cms-reports | C4: A. Customers (`/admin/dashboard/customers`) | D4: P2 | E4: Filter: status active/inactive/banned; isWhatsapp; emailVerified; phoneVerified; gender male/female/other | F4: Correct; invalid enum → error
A5: ADM-CU-004 | B5: 11-admin-users-settings-cms-reports | C5: A. Customers (`/admin/dashboard/customers`) | D5: P2 | E5: Sort name/email/createdAt/updatedAt/lastLoginAt/status | F5: Correct
A6: ADM-CU-005 | B6: 11-admin-users-settings-cms-reports | C6: A. Customers (`/admin/dashboard/customers`) | D6: P2 | E6: pageSize 100 ok / 101 error | F6: per schema
A7: ADM-CU-006 | B7: 11-admin-users-settings-cms-reports | C7: A. Customers (`/admin/dashboard/customers`) | D7: P1 | E7: Customer detail: profile, addresses, orders, cart, wishlist tabs | F7: Data matches customer's own view
A8: ADM-CU-007 | B8: 11-admin-users-settings-cms-reports | C8: A. Customers (`/admin/dashboard/customers`) | D8: P1 | E8: Deactivate customer (`isActive:false`) | F8: Customer cannot log in / place orders
A9: ADM-CU-008 | B9: 11-admin-users-settings-cms-reports | C9: A. Customers (`/admin/dashboard/customers`) | D9: P1 | E9: Reactivate | F9: Works again
A10: ADM-CU-009 | B10: 11-admin-users-settings-cms-reports | C10: A. Customers (`/admin/dashboard/customers`) | D10: P2 | E10: Status body missing / non-boolean | F10: Validation error
A11: ADM-CU-010 | B11: 11-admin-users-settings-cms-reports | C11: A. Customers (`/admin/dashboard/customers`) | D11: P2 | E11: Unknown customer uuid | F11: "Customer not found"
A12: ADM-CU-011 | B12: 11-admin-users-settings-cms-reports | C12: A. Customers (`/admin/dashboard/customers`) | D12: P2 | E12: Customer orders tab filter status/payment/search/sort | F12: Correct
A13: ADM-CU-012 | B13: 11-admin-users-settings-cms-reports | C13: A. Customers (`/admin/dashboard/customers`) | D13: P2 | E13: Guest shadow customers (no password) labelled / listed | F13: Visible, filterable
... A133: WA-014 | B133: 11-admin-users-settings-cms-reports | C133: I. WhatsApp (campaigns, templates, send) | D133: P3 | E133: Phone formats `+91…`, `91…`, 10-digit normalised | F133: Delivered

Sheet 12-security-and-nonfunctional
A1: Test Case ID | B1: Module | C1: Section | D1: Priority | E1: Scenario | F1: Expected Result | G1: Status | H1: Tester | I1: Date | J1: Bug / Ticket | K1: Notes
A2: SEC-001 | B2: 12-security-and-nonfunctional | C2: A. Unauthenticated / broken access control | D2: P0 | E2: `POST /api/admin/reset-database` with no cookie/token (throw-away DB) | F2: Must be 401/403. **Current code: executes wipe** → log as blocker
A3: SEC-002 | B3: 12-security-and-nonfunctional | C3: A. Unauthenticated / broken access control | D3: P0 | E3: Same call as logged-in customer / staff | F3: 403 (admin only, ideally disabled in production)
A4: SEC-003 | B4: 12-security-and-nonfunctional | C4: A. Unauthenticated / broken access control | D4: P0 | E4: `POST /api/admin/whatsapp/send` with no auth and `{phone,message}` | F4: Must be 401; current code sends from the business number
A5: SEC-004 | B5: 12-security-and-nonfunctional | C5: A. Unauthenticated / broken access control | D5: P0 | E5: `GET /api/admin/whatsapp/customers` no auth | F5: Must be 401 (customer phone numbers leak)
A6: SEC-005 | B6: 12-security-and-nonfunctional | C6: A. Unauthenticated / broken access control | D6: P0 | E6: `POST /api/admin/whatsapp/connect` / `disconnect` no auth | F6: Must be 401 (anyone can drop the WhatsApp session)
A7: SEC-006 | B7: 12-security-and-nonfunctional | C7: A. Unauthenticated / broken access control | D7: P0 | E7: `GET/POST /api/admin/whatsapp/campaigns`, `[id]`, `[id]/action`, `templates` no auth | F7: Must be 401/403
A8: SEC-007 | B8: 12-security-and-nonfunctional | C8: A. Unauthenticated / broken access control | D8: P1 | E8: `GET /api/inventory/low-stock` and `/api/inventory/{id}` no auth | F8: Must be 401/403
A9: SEC-008 | B9: 12-security-and-nonfunctional | C9: A. Unauthenticated / broken access control | D9: P1 | E9: Customer token on every `ADMIN`/`ADMIN,STAFF` API (use the matrix in file 14) | F9: 403 each
A10: SEC-009 | B10: 12-security-and-nonfunctional | C10: A. Unauthenticated / broken access control | D10: P1 | E10: Staff token on ADMIN-only APIs (users, roles, permissions, admin/products, agent-payout approve/mark-paid…) | F10: 403
A11: SEC-010 | B11: 12-security-and-nonfunctional | C11: A. Unauthenticated / broken access control | D11: P1 | E11: Agent token on admin/staff APIs | F11: 403
A12: SEC-011 | B12: 12-security-and-nonfunctional | C12: A. Unauthenticated / broken access control | D12: P1 | E12: Admin token on `/api/agent/*` | F12: 403 "Sales Partner access only"
A13: SEC-012 | B13: 12-security-and-nonfunctional | C13: A. Unauthenticated / broken access control | D13: P1 | E13: Forged JWT (alg none / wrong secret / changed role=ADMIN) | F13: 401, no access
... A127: CMP-015 | B127: 12-security-and-nonfunctional | C127: I. Compatibility & accessibility | D127: P3 | E127: Dev-tool hidden pane duplicate Suspense `div#S:0` in in-app browser | F127: Known test artifact, not a bug

Sheet 13-end-to-end-journeys
A1: Test Case ID | B1: Module | C1: Section | D1: Priority | E1: Scenario | F1: Expected Result | G1: Status | H1: Tester | I1: Date | J1: Bug / Ticket | K1: Notes
A2: E2E-001 | B2: 13-end-to-end-journeys | D2: P1 | E2: **Setup chain:** GST rate → HSN → Category → Brand → Unit → Attribute (Colour, Size) → Product (gender men) → Item (SKU, base ₹1000, opening stock) → Generate variants (2 colours × 3 sizes) → set prices → activate | F2: Product visible on storefront with correct colour/size combos, per-row stock = opening stock, opening-stock PO `RECEIVED` under "Opening Stock" vendor, ledger PURCHASE rows
A3: E2E-002 | B3: 13-end-to-end-journeys | D3: P1 | E3: **Gender "Not applicable" product:** create electronics-type product with gender `Not applicable` end-to-end | F3: Saves, appears in listing without gender filter, hidden under gender filter, no size chart error, header menu/size-chart pages still load
A4: E2E-003 | B4: 13-end-to-end-journeys | D4: P1 | E4: **Guest purchase (COD, Tamil Nadu):** browse → add 2 → cart → guest checkout → place | F4: Shipping ₹0, order `confirmed`, stock −2, shadow account, success page, admin sees it in Confirmed
A5: E2E-004 | B5: 13-end-to-end-journeys | D5: P1 | E5: **Guest purchase (COD, Kerala):** same | F5: Shipping ₹80, total correct
A6: E2E-005 | B6: 13-end-to-end-journeys | D6: P1 | E6: **Registered purchase (Razorpay success):** register via OTP → address → coupon → pay with test card | F6: Order `confirmed`+`paid`, amount = total, stock −N, coupon usage +1, invoice downloadable
A7: E2E-006 | B7: 13-end-to-end-journeys | D7: P1 | E7: **Payment failure then retry:** fail card → retry success | F7: One order only, stock deducted once
A8: E2E-007 | B8: 13-end-to-end-journeys | D8: P1 | E8: **Full fulfilment (staff delivery):** confirm → processing → packed → assign staff → staff accepts → out for delivery → delivered | F8: Timeline complete on both sides; `delivered_at` set; commission clock starts (if referred); COD marked paid
A9: E2E-008 | B9: 13-end-to-end-journeys | D9: P1 | E9: **Full fulfilment (courier):** pack → ship with `EE123456789IN` → mark delivered | F9: Tracking link on customer page works
A10: E2E-009 | B10: 13-end-to-end-journeys | D10: P1 | E10: **Customer cancel before packing:** place → cancel (reason) | F10: Stock restored once, paid order refunded, commission cancelled
A11: E2E-010 | B11: 13-end-to-end-journeys | D11: P1 | E11: **Admin cancel after shipping** | F11: Allowed; stock restored; refund; commission reversed
A12: E2E-011 | B12: 13-end-to-end-journeys | D12: P1 | E12: **Return happy path:** delivered → request within 3 days with video → review → approve → pickup → picked up → received → refund → refunded → close | F12: Each customer-visible status; stock +qty on received; payment `refunded`/`partial_refund`; commission reversed for those items
A13: E2E-012 | B13: 13-end-to-end-journeys | D13: P1 | E13: **Return window expiry:** delivered 4 days ago | F13: Request rejected with "return period… expired"
... A44: E2E-043 | B44: 13-end-to-end-journeys | D44: P1 | E44: **Rollback drill:** restore DB backup, confirm app boots and orders intact | F44: Pass
A45: E2E-044 | B45: 13-end-to-end-journeys | C45: Partner journeys | D45: P1 | E45: **Sales Partner onboarding to verified:** admin creates agent → agent logs in → fills personal, address, KYC (Aadhaar/PAN + 2 docs), bank (+ proof) → completion 100% → admin views docs → verifies KYC and bank | F45: Statuses not_submitted → pending → verified; masked numbers only; audit rows; admin sees same %
A46: E2E-045 | B46: 13-end-to-end-journeys | C46: Partner journeys | D46: P1 | E46: **KYC rejection and resubmission:** admin rejects KYC with reason → agent sees reason → corrects PAN, re-uploads PAN card → admin verifies | F46: Rejected → pending (remarks cleared) → verified
A47: E2E-046 | B47: 13-end-to-end-journeys | C47: Partner journeys | D47: P1 | E47: **Verified bank edited:** verified agent changes IFSC | F47: Bank back to pending; admin must re-verify before payout (confirm rule)
A48: E2E-047 | B48: 13-end-to-end-journeys | C48: Partner journeys | D48: P0 | E48: **Sales Partner own purchase:** agent logs in → Purchase Products → cart → checkout → pay → delivered | F48: Order in My Orders + admin "Purchases" tab; NOT in Referral Orders; **no commission row**
A49: E2E-048 | B49: 13-end-to-end-journeys | C49: Partner journeys | D49: P0 | E49: **Own purchase with own referral link:** agent opens own `?ref=` link then buys | F49: Still no commission, no error
A50: E2E-049 | B50: 13-end-to-end-journeys | C50: Partner journeys | D50: P1 | E50: **Agent does both:** customer buys via agent link (commission) and agent buys own items same day | F50: Commission only for the customer's order; dashboards/reports separate the two
A51: E2E-050 | B51: 13-end-to-end-journeys | C51: Partner journeys | D51: P1 | E51: **Own purchase returned/cancelled** | F51: Stock restored, refund as normal, commission tables untouched
A52: E2E-051 | B52: 13-end-to-end-journeys | C52: Partner journeys | D52: P1 | E52: **KYC document security walk-through:** agent A uploads Aadhaar → agent B, customer, guest try its URL/API | F52: Only A and admin/staff can open; storage path not public

Sheet 14-api-authorization-matrix
A1: Test Case ID | B1: Module | C1: Section | D1: Priority | E1: Scenario | F1: Expected Result | G1: Status | H1: Tester | I1: Date | J1: Bug / Ticket | K1: Notes
A2: API-001 | B2: 14-api-authorization-matrix | C2: Admin APIs | D2: P1 | E2: Call GET /api/admin/agent-orders as GUEST / CUSTOMER / AGENT / STAFF / ADMIN | F2: Guest=401 | Customer=403 | Agent=403 | Staff=200 | Admin=200
A3: API-002 | B3: 14-api-authorization-matrix | C3: Admin APIs | D3: P1 | E3: Call POST /api/admin/agent-payouts/[uuid]/approve as GUEST / CUSTOMER / AGENT / STAFF / ADMIN | F3: Guest=401 | Customer=403 | Agent=403 | Staff=403 | Admin=200
A4: API-003 | B4: 14-api-authorization-matrix | C4: Admin APIs | D4: P1 | E4: Call GET /api/admin/agent-payouts/[uuid]/destination as GUEST / CUSTOMER / AGENT / STAFF / ADMIN | F4: Guest=401 | Customer=403 | Agent=403 | Staff=403 | Admin=200
A5: API-004 | B5: 14-api-authorization-matrix | C5: Admin APIs | D5: P1 | E5: Call POST /api/admin/agent-payouts/[uuid]/mark-paid as GUEST / CUSTOMER / AGENT / STAFF / ADMIN | F5: Guest=401 | Customer=403 | Agent=403 | Staff=403 | Admin=200
A6: API-005 | B6: 14-api-authorization-matrix | C6: Admin APIs | D6: P1 | E6: Call POST /api/admin/agent-payouts/[uuid]/reject as GUEST / CUSTOMER / AGENT / STAFF / ADMIN | F6: Guest=401 | Customer=403 | Agent=403 | Staff=403 | Admin=200
A7: API-006 | B7: 14-api-authorization-matrix | C7: Admin APIs | D7: P1 | E7: Call GET /api/admin/agent-payouts as GUEST / CUSTOMER / AGENT / STAFF / ADMIN | F7: Guest=401 | Customer=403 | Agent=403 | Staff=200 | Admin=200
A8: API-007 | B8: 14-api-authorization-matrix | C8: Admin APIs | D8: P1 | E8: Call GET /api/admin/agents/[uuid]/document/[kind] as GUEST / CUSTOMER / AGENT / STAFF / ADMIN | F8: Guest=401 | Customer=403 | Agent=403 | Staff=200 | Admin=200
A9: API-008 | B9: 14-api-authorization-matrix | C9: Admin APIs | D9: P1 | E9: Call GET /api/admin/agents/[uuid]/profile as GUEST / CUSTOMER / AGENT / STAFF / ADMIN | F9: Guest=401 | Customer=403 | Agent=403 | Staff=200 | Admin=200
A10: API-009 | B10: 14-api-authorization-matrix | C10: Admin APIs | D10: P1 | E10: Call GET /api/admin/agents/[uuid]/purchases as GUEST / CUSTOMER / AGENT / STAFF / ADMIN | F10: Guest=401 | Customer=403 | Agent=403 | Staff=200 | Admin=200
A11: API-010 | B11: 14-api-authorization-matrix | C11: Admin APIs | D11: P1 | E11: Call POST /api/admin/agents/[uuid]/review as GUEST / CUSTOMER / AGENT / STAFF / ADMIN | F11: Guest=401 | Customer=403 | Agent=403 | Staff=403 | Admin=200
A12: API-011 | B12: 14-api-authorization-matrix | C12: Admin APIs | D12: P1 | E12: Call GET/PUT/PATCH /api/admin/agents/[uuid] as GUEST / CUSTOMER / AGENT / STAFF / ADMIN | F12: Guest=401 | Customer=403 | Agent=403 | Staff=403 | Admin=200
A13: API-012 | B13: 14-api-authorization-matrix | C13: Admin APIs | D13: P1 | E13: Call GET /api/admin/agents/options as GUEST / CUSTOMER / AGENT / STAFF / ADMIN | F13: Guest=401 | Customer=403 | Agent=403 | Staff=200 | Admin=200
... A290: API-289 | B290: 14-api-authorization-matrix | C290: Legacy / shared APIs | D290: P1 | E290: Call GET/POST /api/users as GUEST / CUSTOMER / AGENT / STAFF / ADMIN | F290: Guest=401 | Customer=403 | Agent=403 | Staff=403 | Admin=200

Sheet 15-agent-profile-kyc-bank
A1: Test Case ID | B1: Module | C1: Section | D1: Priority | E1: Scenario | F1: Expected Result | G1: Status | H1: Tester | I1: Date | J1: Bug / Ticket | K1: Notes
A2: APF-001 | B2: 15-agent-profile-kyc-bank | C2: A. Access & loading (`/agent/profile`) | D2: P1 | E2: [Pos] Login as AGENT, open `/agent/profile` | F2: Wizard + completion card load; saved values pre-filled
A3: APF-002 | B3: 15-agent-profile-kyc-bank | C3: A. Access & loading (`/agent/profile`) | D3: P1 | E3: [Sec] Guest opens `/agent/profile` | F3: Redirect to login
A4: APF-003 | B4: 15-agent-profile-kyc-bank | C4: A. Access & loading (`/agent/profile`) | D4: P1 | E4: [Sec] Customer opens `/agent/profile` | F4: Blocked / redirected (`/unauthorized`)
A5: APF-004 | B5: 15-agent-profile-kyc-bank | C5: A. Access & loading (`/agent/profile`) | D5: P1 | E5: [Sec] ADMIN/STAFF session opens `/agent/profile` | F5: Blocked (AGENT-only)
A6: APF-005 | B6: 15-agent-profile-kyc-bank | C6: A. Access & loading (`/agent/profile`) | D6: P1 | E6: [Sec] `GET /api/agent/profile/details` as CUSTOMER / no session | F6: 403 / 401
A7: APF-006 | B7: 15-agent-profile-kyc-bank | C7: A. Access & loading (`/agent/profile`) | D7: P2 | E7: [Pos] New agent (never saved anything) | F7: All sections empty, completion = only filled name/email/mobile points; status chips "Not submitted"
A8: APF-007 | B8: 15-agent-profile-kyc-bank | C8: A. Access & loading (`/agent/profile`) | D8: P2 | E8: [UI] Loading state while profile fetches | F8: Skeleton/spinner, no flash of empty form
A9: APF-008 | B9: 15-agent-profile-kyc-bank | C9: A. Access & loading (`/agent/profile`) | D9: P2 | E9: [Neg] API returns 500 on load | F9: Error message + retry, no blank white page
A10: APF-009 | B10: 15-agent-profile-kyc-bank | C10: A. Access & loading (`/agent/profile`) | D10: P2 | E10: [Pos] Refresh page mid-wizard | F10: Saved data persists; unsaved typing lost without crash
A11: APF-010 | B11: 15-agent-profile-kyc-bank | C11: A. Access & loading (`/agent/profile`) | D11: P3 | E11: [UI] Agent nav shows "My Profile" active state | F11: Highlighted on `/agent/profile`
A12: APF-011 | B12: 15-agent-profile-kyc-bank | C12: A. Access & loading (`/agent/profile`) | D12: P2 | E12: [Sec] Deactivated (blocked) agent opens profile / calls API | F12: Denied by `requireAgentContext`
A13: APF-012 | B13: 15-agent-profile-kyc-bank | C13: A. Access & loading (`/agent/profile`) | D13: P2 | E13: [Sec] Body contains `user_id` / `agentId` of another agent | F13: Ignored – agent id comes only from session
... A205: APF-204 | B205: 15-agent-profile-kyc-bank | C205: J. Responsive & UX | D205: P2 | E205: [Int] Two tabs editing different steps | F205: Last write per field wins; no wipe of other tab's data (blank = unchanged)

Sheet 16-agent-own-purchase
A1: Test Case ID | B1: Module | C1: Section | D1: Priority | E1: Scenario | F1: Expected Result | G1: Status | H1: Tester | I1: Date | J1: Bug / Ticket | K1: Notes
A2: AOP-001 | B2: 16-agent-own-purchase | D2: P0 | E2: [Int] Agent logged in, no referral cookie, buys 1 product (COD) | F2: Order placed; `agent_id` NULL; **no commission row**
A3: AOP-002 | B3: 16-agent-own-purchase | D3: P0 | E3: [Int] Agent opens **own** referral link/code (`?ref=<own code>`) then buys | F3: Order has no agent_id, no commission, no error shown to user
A4: AOP-003 | B4: 16-agent-own-purchase | D4: P0 | E4: [Int] Agent buys with own `agent_code` (vs `referral_code`) cookie | F4: Same – nothing credited
